Workbook

Sheet TABLERO
A1: 📊 TABLERO DE CONTROL FINANCIERO - NEUROTEA + FAMILIA
A3: Mes seleccionado: | B3: Enero 2026 | D3: Fecha de hoy: | E3: =TODAY()
A5: ═══ 🚨 SUPERVIVENCIA FINANCIERA ═══ | G5: ═══ 📅 LIQUIDEZ SEMANAL ═══
A6: Indicador | B6: Valor | C6: Meta | D6: Estado | G6: Concepto | H6: Cant. | I6: Monto | J6: Acumulado | K6: Estado
A7: 💰 Caja disponible TOTAL ✏️ | B7: 0 | C7: 3 meses gastos | D7: =IF(B7=0,"⚪ Sin datos",IF(B8>=90,"🟢 OK",IF(B8>=30,"🟡 ALERTA","🔴 CRÍTICO"))) | G7: Caja disponible | I7: =B7 | J7: =I7
A8: ⏱️ Días de oxígeno | B8: =IF(B15=0,0,ROUND(B7/B15*30,0)) | C8: ≥ 90 días | D8: =IF(B8=0,"⚪ Sin datos",IF(B8>=90,"🟢 OK",IF(B8>=30,"🟡 ALERTA","🔴 CRÍTICO"))) | G8: 🔴 Atrasados | H8: ✏️ | I8: 0 | J8: =J7-I8 | K8: =IF(I8=0,"🟢",IF(J8>=0,"🟡 Pagar","🔴 Deuda"))
A9: 📋 Gastos pendientes mes | B9: =IFERROR(INDIRECT("'"&B3&"'!C73"),0)+IFERROR(INDIRECT("'"&B3&"'!I65"),0) | C9: Cubrir con caja | D9: =IF(B9=0,"🟢 OK",IF(B9<=B7,"🟢 Cubierto","🔴 No alcanza")) | G9: 📅 Esta semana | H9: ✏️ | I9: 0 | J9: =J8-I9 | K9: =IF(J9>=0,"🟢 Alcanza","🔴 Falta")
A10: ⚠️ Préstamo NT → Familia | B10: =IFERROR(INDIRECT("'"&B3&"'!D6"),0) | C10: 0 (ideal) | D10: =IF(B10=0,"🟢 SANO","🔴 FUGA") | G10: 📅 Próxima semana | H10: ✏️ | I10: 0 | J10: =J9-I10 | K10: =IF(J10>=0,"🟢 Alcanza","🔴 Falta")
G11: SALDO FINAL | J11: =J10 | K11: =IF(J11>=0,"🟢 OK","🔴 DÉFICIT")
A13: ═══ 💵 FLUJO DEL MES ═══ | G13: ═══ 💳 SITUACIÓN DE DEUDAS ═══
A14: Indicador | B14: Familia | C14: NeuroTEA | D14: Total | E14: Estado | G14: Indicador | H14: Valor | K14: Estado
A15: 📈 Ingresos | B15: =IFERROR(INDIRECT("'"&$B$3&"'!D26"),0) | C15: =IFERROR(INDIRECT("'"&$B$3&"'!I15"),0) | D15: =B15+C15 | E15: =IF(D15=0,"⚪",IF(D15>0,"🟢","🔴")) | G15: Deuda TOTAL | H15: =IFERROR(DEUDAS!E28,0) | K15: =IF(H15=0,"🟢","🟡 Activa")
A16: 📉 Egresos | B16: =IFERROR(INDIRECT("'"&$B$3&"'!C72"),0)+IFERROR(INDIRECT("'"&$B$3&"'!C73"),0) | C16: =IFERROR(INDIRECT("'"&$B$3&"'!I64"),0)+IFERROR(INDIRECT("'"&$B$3&"'!I65"),0) | D16: =B16+C16 | E16: =IF(D16=0,"⚪",IF(D16<=D15,"🟢","🔴")) | G16: Cuotas mensuales | H16: =IFERROR(DEUDAS!F28,0) | K16: =IF(H16=0,"🟢",IF(H16<=B17,"🟢 Cubierto","🔴 Excede"))
A17: 📊 Balance | B17: =B15-B16 | C17: =C15-C16 | D17: =D15-D16 | E17: =IF(D17=0,"⚪",IF(D17>0,"🟢 GANASTE","🔴 PERDISTE")) | G17: IPS al día ✏️ | H17: SÍ | K17: =IF(H17="SÍ","🟢","🔴 URGENTE")
G18: IVA al día ✏️ | H18: SÍ | K18: =IF(H18="SÍ","🟢","🔴 URGENTE")
A20: ═══ 🏥 SALUD FINANCIERA NEUROTEA ═══ | G20: ═══ 🛡️ FONDO DE RESERVA ═══
A21: Concepto | B21: % Ideal | C21: Monto Ideal | D21: Monto Real | E21: Estado | G21: Reserva Familiar ✏️ | H21: 0 | K21: =IF(H21=0,"🔴 Sin fondo","🟢")
A22: Gastos Operativos | B22: =Configuración!B20 | C22: =C15*Configuración!B20 | D22: =C16 | E22: =IF(C15=0,"-",IF(D22<=C22,"🟢","🔴")) | G22: Reserva NeuroTEA ✏️ | H22: 0 | K22: =IF(H22=0,"🔴 Sin fondo","🟢")
A23: Compensación dueño | B23: =Configuración!B23 | C23: =C15*Configuración!B23 | D23: 0 | E23: =IF(D23>=C23,"🟢","🔴") | G23: Meta (3 meses gastos) | H23: =D16*3
A24: Fondo emergencia | B24: =Configuración!B24 | C24: =C15*Configuración!B24 | D24: 0 | E24: =IF(D24>=C24,"🟢","🔴") | G24: % Meta alcanzado | H24: =IF(H23=0,0,(H21+H22)/H23) | K24: =IF(H24>=1,"🟢 META",IF(H24>=0.5,"🟡 Avanzando","🔴 Bajo"))
A25: Inversión | B25: =Configuración!B25 | C25: =C15*Configuración!B25 | D25: 0 | E25: =IF(D25>=C25,"🟢","🔴")
A26: Imprevistos | B26: =Configuración!B26 | C26: =C15*Configuración!B26 | D26: 0 | E26: =IF(D26>=C26,"🟢","🔴") | G26: ═══ 📋 ACCIONES DE LA SEMANA ═══
A27: % Gastos / Ingreso NT: | B27: =IF(C15=0,0,D22/C15) | C27: DIAGNÓSTICO: | D27: =IF(C15=0,"⚪ Sin datos",IF(B27<=Configuración!B20,"🟢 CLÍNICA SANA",IF(B27<=1,"🟡 REVISAR","🔴 CRÍTICA"))) | G27: Fecha revisión ✏️
G28: 1.
G29: 2.
G30: 3.
G31: 4.
G32: 5.
A35: ═══ 📊 CUMPLIMIENTO PRESUPUESTO 2026 ═══
B36: ENE | C36: FEB | D36: MAR | E36: ABR | F36: MAY | G36: JUN | H36: JUL | I36: AGO | J36: SEP | K36: OCT | L36: NOV | M36: DIC | N36: TEND.
A37: ► FAMILIA
A38: Ingresos | B38: =IFERROR(INDIRECT("'Enero 2026'!D26")/PRESUPUESTO!B14,"-") | C38: =IFERROR(INDIRECT("'Febrero 2026'!D26")/PRESUPUESTO!C14,"-") | D38: =IFERROR(INDIRECT("'Marzo 2026'!D26")/PRESUPUESTO!D14,"-") | E38: =IFERROR(INDIRECT("'Abril 2026'!D26")/PRESUPUESTO!E14,"-") | F38: =IFERROR(INDIRECT("'Mayo 2026'!D26")/PRESUPUESTO!F14,"-") | G38: =IFERROR(INDIRECT("'Junio 2026'!D26")/PRESUPUESTO!G14,"-") | H38: =IFERROR(INDIRECT("'Julio 2026'!D26")/PRESUPUESTO!H14,"-") | I38: =IFERROR(INDIRECT("'Agosto 2026'!D26")/PRESUPUESTO!I14,"-") | J38: =IFERROR(INDIRECT("'Septiembre 2026'!D26")/PRESUPUESTO!J14,"-") | K38: =IFERROR(INDIRECT("'Octubre 2026'!D26")/PRESUPUESTO!K14,"-") | L38: =IFERROR(INDIRECT("'Noviembre 2026'!D26")/PRESUPUESTO!L14,"-") | M38: =IFERROR(INDIRECT("'Diciembre 2026'!D26")/PRESUPUESTO!M14,"-")
A39: Egresos | B39: =IFERROR((INDIRECT("'Enero 2026'!C72")+INDIRECT("'Enero 2026'!C73"))/PRESUPUESTO!B50,"-") | C39: =IFERROR((INDIRECT("'Febrero 2026'!C72")+INDIRECT("'Febrero 2026'!C73"))/PRESUPUESTO!C50,"-") | D39: =IFERROR((INDIRECT("'Marzo 2026'!C72")+INDIRECT("'Marzo 2026'!C73"))/PRESUPUESTO!D50,"-") | E39: =IFERROR((INDIRECT("'Abril 2026'!C72")+INDIRECT("'Abril 2026'!C73"))/PRESUPUESTO!E50,"-") | F39: =IFERROR((INDIRECT("'Mayo 2026'!C72")+INDIRECT("'Mayo 2026'!C73"))/PRESUPUESTO!F50,"-") | G39: =IFERROR((INDIRECT("'Junio 2026'!C72")+INDIRECT("'Junio 2026'!C73"))/PRESUPUESTO!G50,"-") | H39: =IFERROR((INDIRECT("'Julio 2026'!C72")+INDIRECT("'Julio 2026'!C73"))/PRESUPUESTO!H50,"-") | I39: =IFERROR((INDIRECT("'Agosto 2026'!C72")+INDIRECT("'Agosto 2026'!C73"))/PRESUPUESTO!I50,"-") | J39: =IFERROR((INDIRECT("'Septiembre 2026'!C72")+INDIRECT("'Septiembre 2026'!C73"))/PRESUPUESTO!J50,"-") | K39: =IFERROR((INDIRECT("'Octubre 2026'!C72")+INDIRECT("'Octubre 2026'!C73"))/PRESUPUESTO!K50,"-") | L39: =IFERROR((INDIRECT("'Noviembre 2026'!C72")+INDIRECT("'Noviembre 2026'!C73"))/PRESUPUESTO!L50,"-") | M39: =IFERROR((INDIRECT("'Diciembre 2026'!C72")+INDIRECT("'Diciembre 2026'!C73"))/PRESUPUESTO!M50,"-")
A40: Balance | B40: =IF(OR(C38="-",C39="-"),"-",IF(AND(C38>=1,C39<=1),"🟢",IF(AND(C38>=0.95,C39<=1.05),"🟡","🔴"))) | C40: =IF(OR(D38="-",D39="-"),"-",IF(AND(D38>=1,D39<=1),"🟢",IF(AND(D38>=0.95,D39<=1.05),"🟡","🔴"))) | D40: =IF(OR(E38="-",E39="-"),"-",IF(AND(E38>=1,E39<=1),"🟢",IF(AND(E38>=0.95,E39<=1.05),"🟡","🔴"))) | E40: =IF(OR(F38="-",F39="-"),"-",IF(AND(F38>=1,F39<=1),"🟢",IF(AND(F38>=0.95,F39<=1.05),"🟡","🔴"))) | F40: =IF(OR(G38="-",G39="-"),"-",IF(AND(G38>=1,G39<=1),"🟢",IF(AND(G38>=0.95,G39<=1.05),"🟡","🔴"))) | G40: =IF(OR(H38="-",H39="-"),"-",IF(AND(H38>=1,H39<=1),"🟢",IF(AND(H38>=0.95,H39<=1.05),"🟡","🔴"))) | H40: =IF(OR(I38="-",I39="-"),"-",IF(AND(I38>=1,I39<=1),"🟢",IF(AND(I38>=0.95,I39<=1.05),"🟡","🔴"))) | I40: =IF(OR(J38="-",J39="-"),"-",IF(AND(J38>=1,J39<=1),"🟢",IF(AND(J38>=0.95,J39<=1.05),"🟡","🔴"))) | ... M40: =IF(OR(N38="-",N39="-"),"-",IF(AND(N38>=1,N39<=1),"🟢",IF(AND(N38>=0.95,N39<=1.05),"🟡","🔴")))
A41: ► NEUROTEA
A42: Ingresos | B42: =IFERROR(INDIRECT("'Enero 2026'!I15")/PRESUPUESTO!B59,"-") | C42: =IFERROR(INDIRECT("'Febrero 2026'!I15")/PRESUPUESTO!C59,"-") | D42: =IFERROR(INDIRECT("'Marzo 2026'!I15")/PRESUPUESTO!D59,"-") | E42: =IFERROR(INDIRECT("'Abril 2026'!I15")/PRESUPUESTO!E59,"-") | F42: =IFERROR(INDIRECT("'Mayo 2026'!I15")/PRESUPUESTO!F59,"-") | G42: =IFERROR(INDIRECT("'Junio 2026'!I15")/PRESUPUESTO!G59,"-") | H42: =IFERROR(INDIRECT("'Julio 2026'!I15")/PRESUPUESTO!H59,"-") | I42: =IFERROR(INDIRECT("'Agosto 2026'!I15")/PRESUPUESTO!I59,"-") | J42: =IFERROR(INDIRECT("'Septiembre 2026'!I15")/PRESUPUESTO!J59,"-") | K42: =IFERROR(INDIRECT("'Octubre 2026'!I15")/PRESUPUESTO!K59,"-") | L42: =IFERROR(INDIRECT("'Noviembre 2026'!I15")/PRESUPUESTO!L59,"-") | M42: =IFERROR(INDIRECT("'Diciembre 2026'!I15")/PRESUPUESTO!M59,"-")
A43: Egresos | B43: =IFERROR((INDIRECT("'Enero 2026'!I64")+INDIRECT("'Enero 2026'!I65"))/PRESUPUESTO!B91,"-") | C43: =IFERROR((INDIRECT("'Febrero 2026'!I64")+INDIRECT("'Febrero 2026'!I65"))/PRESUPUESTO!C91,"-") | D43: =IFERROR((INDIRECT("'Marzo 2026'!I64")+INDIRECT("'Marzo 2026'!I65"))/PRESUPUESTO!D91,"-") | E43: =IFERROR((INDIRECT("'Abril 2026'!I64")+INDIRECT("'Abril 2026'!I65"))/PRESUPUESTO!E91,"-") | F43: =IFERROR((INDIRECT("'Mayo 2026'!I64")+INDIRECT("'Mayo 2026'!I65"))/PRESUPUESTO!F91,"-") | G43: =IFERROR((INDIRECT("'Junio 2026'!I64")+INDIRECT("'Junio 2026'!I65"))/PRESUPUESTO!G91,"-") | H43: =IFERROR((INDIRECT("'Julio 2026'!I64")+INDIRECT("'Julio 2026'!I65"))/PRESUPUESTO!H91,"-") | I43: =IFERROR((INDIRECT("'Agosto 2026'!I64")+INDIRECT("'Agosto 2026'!I65"))/PRESUPUESTO!I91,"-") | J43: =IFERROR((INDIRECT("'Septiembre 2026'!I64")+INDIRECT("'Septiembre 2026'!I65"))/PRESUPUESTO!J91,"-") | K43: =IFERROR((INDIRECT("'Octubre 2026'!I64")+INDIRECT("'Octubre 2026'!I65"))/PRESUPUESTO!K91,"-") | L43: =IFERROR((INDIRECT("'Noviembre 2026'!I64")+INDIRECT("'Noviembre 2026'!I65"))/PRESUPUESTO!L91,"-") | M43: =IFERROR((INDIRECT("'Diciembre 2026'!I64")+INDIRECT("'Diciembre 2026'!I65"))/PRESUPUESTO!M91,"-")
A44: Balance | B44: =IF(OR(C42="-",C43="-"),"-",IF(AND(C42>=1,C43<=1),"🟢",IF(AND(C42>=0.95,C43<=1.05),"🟡","🔴"))) | C44: =IF(OR(D42="-",D43="-"),"-",IF(AND(D42>=1,D43<=1),"🟢",IF(AND(D42>=0.95,D43<=1.05),"🟡","🔴"))) | D44: =IF(OR(E42="-",E43="-"),"-",IF(AND(E42>=1,E43<=1),"🟢",IF(AND(E42>=0.95,E43<=1.05),"🟡","🔴"))) | E44: =IF(OR(F42="-",F43="-"),"-",IF(AND(F42>=1,F43<=1),"🟢",IF(AND(F42>=0.95,F43<=1.05),"🟡","🔴"))) | F44: =IF(OR(G42="-",G43="-"),"-",IF(AND(G42>=1,G43<=1),"🟢",IF(AND(G42>=0.95,G43<=1.05),"🟡","🔴"))) | G44: =IF(OR(H42="-",H43="-"),"-",IF(AND(H42>=1,H43<=1),"🟢",IF(AND(H42>=0.95,H43<=1.05),"🟡","🔴"))) | H44: =IF(OR(I42="-",I43="-"),"-",IF(AND(I42>=1,I43<=1),"🟢",IF(AND(I42>=0.95,I43<=1.05),"🟡","🔴"))) | I44: =IF(OR(J42="-",J43="-"),"-",IF(AND(J42>=1,J43<=1),"🟢",IF(AND(J42>=0.95,J43<=1.05),"🟡","🔴"))) | ... M44: =IF(OR(N42="-",N43="-"),"-",IF(AND(N42>=1,N43<=1),"🟢",IF(AND(N42>=0.95,N43<=1.05),"🟡","🔴")))
A46: Leyenda: Ingresos 🟢≥100% 🟡95-99% 🔴<95% | Egresos 🟢≤100% 🟡101-105% 🔴>105% | Balance: combina ambos

Sheet PRESUPUESTO
A1: 📊 PRESUPUESTO ANUAL 2026
A2: Cargar los montos previstos para cada mes. El sistema comparará automáticamente con los gastos reales.
A4: CONCEPTO | B4: ENE | C4: FEB | D4: MAR | E4: ABR | F4: MAY | G4: JUN | H4: JUL | I4: AGO | J4: SEP | K4: OCT | L4: NOV | M4: DIC | N4: TOTAL AÑO
A5: ═══ PRESUPUESTO FAMILIA ═══
A6: ► INGRESOS FAMILIA
A7: Salario Marco | B7: 0 | C7: 0 | D7: 0 | E7: 0 | F7: 0 | G7: 0 | H7: 0 | I7: 0 | J7: 0 | K7: 0 | L7: 0 | M7: 0 | N7: =SUM(B7:M7)
A8: Vacaciones Marco | B8: 0 | C8: 0 | D8: 0 | E8: 0 | F8: 0 | G8: 0 | H8: 0 | I8: 0 | J8: 0 | K8: 0 | L8: 0 | M8: 0 | N8: =SUM(B8:M8)
A9: Aguinaldo Marco | B9: 0 | C9: 0 | D9: 0 | E9: 0 | F9: 0 | G9: 0 | H9: 0 | I9: 0 | J9: 0 | K9: 0 | L9: 0 | M9: 0 | N9: =SUM(B9:M9)
A10: Viático Marco | B10: 0 | C10: 0 | D10: 0 | E10: 0 | F10: 0 | G10: 0 | H10: 0 | I10: 0 | J10: 0 | K10: 0 | L10: 0 | M10: 0 | N10: =SUM(B10:M10)
A11: Animador Bíblico | B11: 0 | C11: 0 | D11: 0 | E11: 0 | F11: 0 | G11: 0 | H11: 0 | I11: 0 | J11: 0 | K11: 0 | L11: 0 | M11: 0 | N11: =SUM(B11:M11)
A12: Otros Ingresos Marco | B12: 0 | C12: 0 | D12: 0 | E12: 0 | F12: 0 | G12: 0 | H12: 0 | I12: 0 | J12: 0 | K12: 0 | L12: 0 | M12: 0 | N12: =SUM(B12:M12)
A13: Honorarios Clara | B13: 0 | C13: 0 | D13: 0 | E13: 0 | F13: 0 | G13: 0 | H13: 0 | I13: 0 | J13: 0 | K13: 0 | L13: 0 | M13: 0 | N13: =SUM(B13:M13)
A14: TOTAL INGRESOS FAMILIA | B14: =SUM(B7:B13) | C14: =SUM(C7:C13) | D14: =SUM(D7:D13) | E14: =SUM(E7:E13) | F14: =SUM(F7:F13) | G14: =SUM(G7:G13) | H14: =SUM(H7:H13) | I14: =SUM(I7:I13) | ... N14: =SUM(N7:N13)
A15: ► EGRESOS FAMILIA - GASTOS FIJOS
A16: Salario Lili Doméstico | B16: 0 | C16: 0 | D16: 0 | E16: 0 | F16: 0 | G16: 0 | H16: 0 | I16: 0 | J16: 0 | K16: 0 | L16: 0 | M16: 0 | N16: =SUM(B16:M16)
A17: Salario Laura Doméstico | B17: 0 | C17: 0 | D17: 0 | E17: 0 | F17: 0 | G17: 0 | H17: 0 | I17: 0 | J17: 0 | K17: 0 | L17: 0 | M17: 0 | N17: =SUM(B17:M17)
A18: Escuela Fabián y Brenda | B18: 0 | C18: 0 | D18: 0 | E18: 0 | F18: 0 | G18: 0 | H18: 0 | I18: 0 | J18: 0 | K18: 0 | L18: 0 | M18: 0 | N18: =SUM(B18:M18)
A19: Robótica Niños | B19: 0 | C19: 0 | D19: 0 | E19: 0 | F19: 0 | G19: 0 | H19: 0 | I19: 0 | J19: 0 | K19: 0 | L19: 0 | M19: 0 | N19: =SUM(B19:M19)
A20: ANDE Casa | B20: 0 | C20: 0 | D20: 0 | E20: 0 | F20: 0 | G20: 0 | H20: 0 | I20: 0 | J20: 0 | K20: 0 | L20: 0 | M20: 0 | N20: =SUM(B20:M20)
A21: Expensa Casa | B21: 0 | C21: 0 | D21: 0 | E21: 0 | F21: 0 | G21: 0 | H21: 0 | I21: 0 | J21: 0 | K21: 0 | L21: 0 | M21: 0 | N21: =SUM(B21:M21)
A22: Cajubi Marco | B22: 0 | C22: 0 | D22: 0 | E22: 0 | F22: 0 | G22: 0 | H22: 0 | I22: 0 | J22: 0 | K22: 0 | L22: 0 | M22: 0 | N22: =SUM(B22:M22)
A23: Mutual Marco | B23: 0 | C23: 0 | D23: 0 | E23: 0 | F23: 0 | G23: 0 | H23: 0 | I23: 0 | J23: 0 | K23: 0 | L23: 0 | M23: 0 | N23: =SUM(B23:M23)
A24: Ña Luisa | B24: 0 | C24: 0 | D24: 0 | E24: 0 | F24: 0 | G24: 0 | H24: 0 | I24: 0 | J24: 0 | K24: 0 | L24: 0 | M24: 0 | N24: =SUM(B24:M24)
A25: Seguro Médico Papá y Mamá | B25: 0 | C25: 0 | D25: 0 | E25: 0 | F25: 0 | G25: 0 | H25: 0 | I25: 0 | J25: 0 | K25: 0 | L25: 0 | M25: 0 | N25: =SUM(B25:M25)
A26: ► EGRESOS FAMILIA - CUOTAS Y PRÉSTAMOS
A27: Auto Laura Cuota | B27: 0 | C27: 0 | D27: 0 | E27: 0 | F27: 0 | G27: 0 | H27: 0 | I27: 0 | J27: 0 | K27: 0 | L27: 0 | M27: 0 | N27: =SUM(B27:M27)
A28: Coop. Universitaria Clara | B28: 0 | C28: 0 | D28: 0 | E28: 0 | F28: 0 | G28: 0 | H28: 0 | I28: 0 | J28: 0 | K28: 0 | L28: 0 | M28: 0 | N28: =SUM(B28:M28)
A29: Coomecipar Clara | B29: 0 | C29: 0 | D29: 0 | E29: 0 | F29: 0 | G29: 0 | H29: 0 | I29: 0 | J29: 0 | K29: 0 | L29: 0 | M29: 0 | N29: =SUM(B29:M29)
A30: Tarjeta Cred. Coomecipar | B30: 0 | C30: 0 | D30: 0 | E30: 0 | F30: 0 | G30: 0 | H30: 0 | I30: 0 | J30: 0 | K30: 0 | L30: 0 | M30: 0 | N30: =SUM(B30:M30)
A31: Solar Préstamo 1 | B31: 0 | C31: 0 | D31: 0 | E31: 0 | F31: 0 | G31: 0 | H31: 0 | I31: 0 | J31: 0 | K31: 0 | L31: 0 | M31: 0 | N31: =SUM(B31:M31)
A32: Solar Préstamo 2 | B32: 0 | C32: 0 | D32: 0 | E32: 0 | F32: 0 | G32: 0 | H32: 0 | I32: 0 | J32: 0 | K32: 0 | L32: 0 | M32: 0 | N32: =SUM(B32:M32)
A33: Préstamo Lizzi Sueldos | B33: 0 | C33: 0 | D33: 0 | E33: 0 | F33: 0 | G33: 0 | H33: 0 | I33: 0 | J33: 0 | K33: 0 | L33: 0 | M33: 0 | N33: =SUM(B33:M33)
A34: Show Congelador | B34: 0 | C34: 0 | D34: 0 | E34: 0 | F34: 0 | G34: 0 | H34: 0 | I34: 0 | J34: 0 | K34: 0 | L34: 0 | M34: 0 | N34: =SUM(B34:M34)
A35: Olier Heladera | B35: 0 | C35: 0 | D35: 0 | E35: 0 | F35: 0 | G35: 0 | H35: 0 | I35: 0 | J35: 0 | K35: 0 | L35: 0 | M35: 0 | N35: =SUM(B35:M35)
A36: ► EGRESOS FAMILIA - SUSCRIPCIONES
A37: Giganet | B37: 0 | C37: 0 | D37: 0 | E37: 0 | F37: 0 | G37: 0 | H37: 0 | I37: 0 | J37: 0 | K37: 0 | L37: 0 | M37: 0 | N37: =SUM(B37:M37)
A38: Tigo Internet/Celulares | B38: 0 | C38: 0 | D38: 0 | E38: 0 | F38: 0 | G38: 0 | H38: 0 | I38: 0 | J38: 0 | K38: 0 | L38: 0 | M38: 0 | N38: =SUM(B38:M38)
A39: Tigo Familiar | B39: 0 | C39: 0 | D39: 0 | E39: 0 | F39: 0 | G39: 0 | H39: 0 | I39: 0 | J39: 0 | K39: 0 | L39: 0 | M39: 0 | N39: =SUM(B39:M39)
A40: Google One | B40: 0 | C40: 0 | D40: 0 | E40: 0 | F40: 0 | G40: 0 | H40: 0 | I40: 0 | J40: 0 | K40: 0 | L40: 0 | M40: 0 | N40: =SUM(B40:M40)
A41: ChatGPT | B41: 0 | C41: 0 | D41: 0 | E41: 0 | F41: 0 | G41: 0 | H41: 0 | I41: 0 | J41: 0 | K41: 0 | L41: 0 | M41: 0 | N41: =SUM(B41:M41)
...

Sheet DIAGNÓSTICO
A1: 📋 DIAGNÓSTICO INICIAL - Completar una sola vez
A3: Fecha del diagnóstico:
A5: ═══ 💰 CAJA DISPONIBLE HOY ═══
A6: Cuenta | B6: Saldo actual | C6: Notas
A7: Atlas (NeuroTEA) | B7: 0 | C7: Cuenta de la clínica
A8: ITAU Marco | B8: 0 | C8: Cuenta personal Marco
A9: ITAU Clara | B9: 0 | C9: Cuenta personal Clara
A10: UENO Clara | B10: 0 | C10: Cuenta secundaria Clara
A11: Coop. Univ. Marco | B11: 0 | C11: Cooperativa
A12: Caja NT | B12: 0 | C12: Efectivo en la clínica
A13: Efectivo en mano | B13: 0 | C13: Efectivo personal
A14: TOTAL CAJA DISPONIBLE: | B14: =SUM(B7:B13)
A16: ═══ 📉 GASTOS MENSUALES ESENCIALES ═══
A17: Concepto | B17: Monto mensual
A18: Gastos fijos Familia (salarios, escuela, servicios) | B18: 0
A19: Cuotas y préstamos Familia | B19: 0
A20: Gastos fijos NeuroTEA (alquiler, sueldos) | B20: 0
A21: IPS + IVA | B21: 0
A22: Gastos personales mínimos (comida, transporte) | B22: 0
A23: TOTAL GASTOS MENSUALES: | B23: =SUM(B18:B22)
A25: ═══ ⏱️ DÍAS DE OXÍGENO ═══
A26: Gasto diario promedio: | B26: =B23/30
A27: DÍAS QUE PODÉS OPERAR: | B27: =IF(B26=0,0,ROUND(B14/B26,0)) | C27: =IF(B27>=90,"🟢 ESTABLE",IF(B27>=30,"🟡 ALERTA","🔴 EMERGENCIA"))

Sheet DEUDAS
A1: 📋 REGISTRO DE DEUDAS - Ordenar por prioridad de pago
A3: ⚠️ PRIORIDAD: 1=IPS/Impuestos, 2=Salarios, 3=Alquiler/Servicios, 4=Proveedores, 5=Bancos/Tarjetas, 6=Familiares
A5: Prior. | B5: Acreedor | C5: Tipo | D5: Detalle | E5: Monto Total | F5: Cuota Mensual | G5: Cuotas Pend. | H5: Estado
A6: 1 | B6: IPS | C6: Impuesto | D6: Aportes patronales | E6: 0 | F6: 0 | G6: 0 | H6: Pendiente
A7: 1 | B7: SET (IVA) | C7: Impuesto | D7: IVA mensual | E7: 0 | F7: 0 | G7: 0 | H7: Pendiente
A8: 2 | B8: Aracely | C8: Salario | D8: Sueldo secretaria | E8: 0 | F8: 0 | G8: 1 | H8: Pendiente
A9: 2 | B9: Fátima | C9: Salario | D9: Sueldo secretaria | E9: 0 | F9: 0 | G9: 1 | H9: Pendiente
A10: 3 | B10: Alquiler local | C10: Alquiler | D10: Local NeuroTEA | E10: 0 | F10: 0 | G10: 1 | H10: Pendiente
A11: 4 | B11: Contador | C11: Servicio | D11: Honorarios | E11: 0 | F11: 0 | G11: 0 | H11: Pendiente
A12: 5 | B12: Solar Préstamo 1 | C12: Préstamo | E12: 0 | F12: 0 | G12: 0 | H12: Pendiente
A13: 5 | B13: Solar Préstamo 2 | C13: Préstamo | E13: 0 | F13: 0 | G13: 0 | H13: Pendiente
A14: 5 | B14: Coop. Universitaria | C14: Préstamo | E14: 0 | F14: 0 | G14: 0 | H14: Pendiente
A15: 5 | B15: Coomecipar Clara | C15: Préstamo | E15: 0 | F15: 0 | G15: 0 | H15: Pendiente
A16: 5 | B16: Tarjeta Coomecipar | C16: Tarjeta | E16: 0 | F16: 0 | G16: 0 | H16: Pendiente
A17: 5 | B17: Auto Laura | C17: Préstamo | D17: Cuota vehículo | E17: 0 | F17: 0 | G17: 0 | H17: Pendiente
A18: 6 | B18: Préstamo Lizzi | C18: Familiar | D18: Sueldos | E18: 0 | F18: 0 | G18: 0 | H18: Pendiente
A19: 6 | B19: Show Congelador | C19: Familiar | E19: 0 | F19: 0 | G19: 0 | H19: Pendiente
A20: 6 | B20: Olier Heladera | C20: Familiar | E20: 0 | F20: 0 | G20: 0 | H20: Pendiente
A28: TOTALES: | E28: =SUM(E6:E25) | F28: =SUM(F6:F25)
A30: ═══ 📊 RESUMEN POR PRIORIDAD ═══
A31: Prioridad 1 (IPS/Impuestos) | B31: =SUMIF(A6:A25,1,F6:F25) | C31: 🔴 Pagar PRIMERO
A32: Prioridad 2 (Salarios) | B32: =SUMIF(A6:A25,2,F6:F25) | C32: 🔴 Pagar SEGUNDO
A33: Prioridad 3 (Alquiler/Servicios) | B33: =SUMIF(A6:A25,3,F6:F25) | C33: 🟡 Pagar TERCERO
A34: Prioridad 4 (Proveedores) | B34: =SUMIF(A6:A25,4,F6:F25) | C34: 🟡 Negociar plazos
A35: Prioridad 5 (Bancos/Tarjetas) | B35: =SUMIF(A6:A25,5,F6:F25) | C35: 🟢 Refinanciar si es necesario
A36: Prioridad 6 (Familiares) | B36: =SUMIF(A6:A25,6,F6:F25) | C36: 🟢 Más flexible

Sheet Configuración
A1: ⚙️ CONFIGURACIÓN
A3: Cat. Familiar | B3: Cat. NeuroTEA | C3: Eventos NT | D3: Eventos NT | E3: Cat. Ingresos | F3: Tipos | G3: Estados | H3: Cuentas
A4: Combustible | B4: Insumos NT | C4: Día del Niño NT | D4: Atlas (NeuroTEA) | E4: Salario Mensual | F4: Ingreso NT | G4: Ninguno | H4: Atlas (NeuroTEA)
A5: Supermercado | B5: Papelería NT | C5: San Juan NT | D5: ITAU Marco | E5: Vacaciones | F5: Ingreso Marco | G5: Pendiente | H5: ITAU Marco
A6: Farmacia | B6: Mantenimiento NT | C6: Día del Autismo NT | D6: ITAU Clara | E6: Aguinaldo | F6: Ingreso Clara | G6: Pagado | H6: ITAU Clara
A7: Recreación | B7: Gastos Cursos NT | C7: Clausura Padres NT | D7: UENO Clara | E7: Viático | F7: Egreso NT | G7: Cancelado | H7: UENO Clara
A8: Gastos Varios | B8: Gastos Varios NT | C8: Navidad Papá Noel NT | D8: Coop. Univ. Marco | E8: Animador Bíblico | F8: Egreso Familiar | H8: Coop. Univ. Marco
A9: Reserva Fam 1 | B9: Reserva NT 1 | C9: Cena Fin de Año NT | D9: Efectivo | E9: Otros Ocasionales | F9: Préstamo NT → Familia | H9: Efectivo
A10: Reserva Fam 2 | B10: Reserva NT 2 | C10: Evento Reserva 1 | D10: Caja NT | E10: Honorarios Diarios | F10: Devolución Familia → NT | H10: Caja NT
A11: Reserva Fam 3 | B11: Reserva NT 3 | C11: Evento Reserva 2 | E11: Sesiones Terapia
A14: 📌 Para agregar categoría, renombrá una 'Reserva'.
A16: 📊 PARÁMETROS DE SALUD FINANCIERA NT
A18: Parámetro | B18: Valor | C18: Descripción
A19: % Ganancia Objetivo | B19: 0.07 | C19: ✏️ Editar para ajustar umbrales
A20: % Gastos Máximo | B20: =1-B19 | C20: Calculado automáticamente
A22: Subdivisión de la Ganancia:
A23: Compensación dueño | B23: =B19/4 | C23: Utilidad adicional al sueldo fijo
A24: Fondo emergencia | B24: =B19/4 | C24: Reserva para imprevistos
A25: Inversión | B25: =B19/4 | C25: Crecimiento y mejoras
A26: Imprevistos/Desvío | B26: =B19/4 | C26: Colchón adicional
A28: Umbrales de Diagnóstico:
A29: 🟢 Clínica Sana | B29: =B20 | C29: Gastos ≤ este valor
A30: 🟡 Revisar Gastos | B30: 100% | C30: Gastos entre verde y 100%
A31: 🔴 Situación Crítica | B31: >100% | C31: Pérdida operativa

Sheet Ing-Egr Enero 2026
A1: 📋 REGISTRO DE MOVIMIENTOS - ENERO 2026
A3: Fecha | B3: Tipo | C3: Categoría | D3: Descripción | E3: Ingreso | F3: Egreso | G3: Cuenta | H3: Notas
A104: TOTALES | E104: =SUM(E4:E103) | F104: =SUM(F4:F103)
A106: 📊 RESUMEN DEL MES
A107: INGRESOS: | C107: =SUMIF(B4:B103,"Ingreso NT",E4:E103)
A108: Ingreso NT: | C108: =SUMIF(B4:B103,"Ingreso NT",E4:E103)
A109: Ingreso Marco: | C109: =SUMIF(B4:B103,"Ingreso Marco",E4:E103)
A110: Ingreso Clara: | C110: =SUMIF(B4:B103,"Ingreso Clara",E4:E103)
A111: Devolución Fam → NT: | C111: =SUMIF(B4:B103,"Devolución Familia → NT",E4:E103)
A112: TOTAL INGRESOS: | C112: =SUM(C108:C111)
A113: EGRESOS:
A114: EGRESOS: | C114: =SUMIF(B4:B103,"Egreso NT",F4:F103)
A115: Egreso NT: | C115: =SUMIF(B4:B103,"Egreso NT",F4:F103)
A116: Egreso Familiar: | C116: =SUMIF(B4:B103,"Egreso Familiar",F4:F103)
A117: Préstamo NT → Fam: | C117: =SUMIF(B4:B103,"Préstamo NT → Familia",F4:F103)
A118: TOTAL EGRESOS: | C118: =SUM(C115:C117)
A120: SALDO PRÉSTAMO NT → FAM: | C120: =C117-C111
A121: (Prestado - Devuelto)

Sheet Enero 2026
A1: 📊 CONTROL FINANCIERO - ENERO 2026
A3: TOTAL INGRESOS | D3: GASTOS PAGADOS | G3: GASTOS PENDIENTES | J3: BALANCE
A4: =D26+J12 | D4: =D65+I58 | G4: =D66+I59 | J4: =A4-D4-G4
A6: ⚠️ PRÉSTAMO NT → FAMILIA | D6: =SUMIF('Ing-Egr Enero 2026'!B4:B103,"Préstamo NT → Familia",'Ing-Egr Enero 2026'!F4:F103)-SUMIF('Ing-Egr Enero 2026'!B4:B103,"Devolución Familia → NT",'Ing-Egr Enero 2026'!E4:E103) | F6: Estado: | G6: =IF(D6=0,"🟢 SANO","🔴 FUGA") | I6: (Ideal = 0)
A8: 💵 INGRESOS FAMILIA | G8: 💵 INGRESOS NEUROTEA
A9: MARCO ITAIPU | C9: Fecha | D9: Monto | G9: Ingreso del Mes | J9: Monto
A10: Salario Mensual | D10: =SUMIFS('Ing-Egr Enero 2026'!E4:E103,'Ing-Egr Enero 2026'!B4:B103,"Ingreso Marco",'Ing-Egr Enero 2026'!C4:C103,A10) | G10: (Suma desde pestaña Ing-Egr Enero) | J10: =SUMIF('Ing-Egr Enero 2026'!B4:B103,"Ingreso NT",'Ing-Egr Enero 2026'!E4:E103)
A11: Vacaciones | D11: =SUMIFS('Ing-Egr Enero 2026'!E4:E103,'Ing-Egr Enero 2026'!B4:B103,"Ingreso Marco",'Ing-Egr Enero 2026'!C4:C103,A11)
A12: Aguinaldo | D12: =SUMIFS('Ing-Egr Enero 2026'!E4:E103,'Ing-Egr Enero 2026'!B4:B103,"Ingreso Marco",'Ing-Egr Enero 2026'!C4:C103,A12) | G12: ═══ TOTAL INGRESOS NT ═══ | J12: =J10
A13: Viático | D13: =SUMIFS('Ing-Egr Enero 2026'!E4:E103,'Ing-Egr Enero 2026'!B4:B103,"Ingreso Marco",'Ing-Egr Enero 2026'!C4:C103,A13)
A14: Animador Bíblico | D14: =SUMIFS('Ing-Egr Enero 2026'!E4:E103,'Ing-Egr Enero 2026'!B4:B103,"Ingreso Marco",'Ing-Egr Enero 2026'!C4:C103,A14)
A15: Otros Ocasionales | D15: =SUMIFS('Ing-Egr Enero 2026'!E4:E103,'Ing-Egr Enero 2026'!B4:B103,"Ingreso Marco",'Ing-Egr Enero 2026'!C4:C103,A15) | I15: =J12
A16: TOTAL MARCO | D16: =SUM(D10:D15)
A17: CLARA | C17: Fecha | D17: Monto
A18: Honorarios Diarios | D18: =SUMIF('Ing-Egr Enero 2026'!B4:B103,"Ingreso Clara",'Ing-Egr Enero 2026'!E4:E103)
A19: TOTAL CLARA | D19: =D18
A20: DESDE NEUROTEA | D20: Monto
A21: Salario Admin Marco | D21: 0
A22: Ganancia NT → Familia | D22: 0
A23: Préstamo NT (automático) | D23: =D6
A24: TOTAL DESDE NT | D24: =SUM(D21:D23)
A26: ═══ TOTAL INGRESOS FAMILIA ═══ | D26: =D16+D19+D24
A28: 📉 GASTOS FAMILIARES | G28: 📉 GASTOS NEUROTEA
A29: Detalle | B29: Estado | C29: Monto | D29: Venc. | G29: Detalle | H29: Estado | I29: Monto | J29: Venc.
A30: ► GASTOS FIJOS ✏️ | G30: ► GASTOS FIJOS ✏️
A31: Salario Lili Doméstico | B31: Ninguno | G31: Alquiler 1 (Principal) | H31: Ninguno | I31: 0
A32: Salario Laura Doméstico | B32: Ninguno | G32: Alquiler 2 (Secundario) | H32: Ninguno | I32: 0
A33: Escuela Fabián y Brenda | B33: Ninguno | G33: Limpieza NeuroTEA | H33: Ninguno | I33: 0
A34: Robótica Niños | B34: Ninguno | G34: ► SUELDOS Y HONORARIOS ✏️
A35: ANDE Casa | B35: Ninguno | G35: Sueldo Aracely | H35: Ninguno | I35: 0
A36: Expensa Casa | B36: Ninguno | G36: Sueldo Fátima | H36: Ninguno | I36: 0
A37: Cajubi Marco | B37: Ninguno | G37: Honorario Contador | H37: Ninguno | I37: 0
A38: Mutual Marco | B38: Ninguno | G38: Salario Administrador | H38: Ninguno | I38: 0
A39: Ña Luisa | B39: Ninguno | G39: Honorario Mant. Sistema | H39: Ninguno | I39: 0
A40: Seguro Médico Papá y Mamá | B40: Ninguno | G40: ► TELEFONÍA E INTERNET ✏️
A41: ► CUOTAS Y PRÉSTAMOS ✏️ | G41: Celular Tigo NeuroTEA | H41: Ninguno | I41: 0
A42: Auto Laura Cuota | B42: Ninguno | G42: Celular Tigo Sistema | H42: Ninguno | I42: 0
A43: Coop. Universitaria Clara | B43: Ninguno | G43: WhatsFlow | H43: Ninguno | I43: 0
A44: Coomecipar Clara | B44: Ninguno | G44: Internet NeuroTEA | H44: Ninguno | I44: 0
A45: Tarjeta Cred. Coomecipar | B45: Ninguno | G45: ► IMPUESTOS ✏️
...

Sheet Ing-Egr Febrero 2026
A1: 📋 REGISTRO DE MOVIMIENTOS - FEBRERO 2026
A3: Fecha | B3: Tipo | C3: Categoría | D3: Descripción | E3: Ingreso | F3: Egreso | G3: Cuenta | H3: Notas
A104: TOTALES | E104: =SUM(E4:E103) | F104: =SUM(F4:F103)
A106: 📊 RESUMEN DEL MES
A107: INGRESOS: | C107: =SUMIF(B4:B103,"Ingreso NT",E4:E103)
A108: Ingreso NT: | C108: =SUMIF(B4:B103,"Ingreso NT",E4:E103)
A109: Ingreso Marco: | C109: =SUMIF(B4:B103,"Ingreso Marco",E4:E103)
A110: Ingreso Clara: | C110: =SUMIF(B4:B103,"Ingreso Clara",E4:E103)
A111: Devolución Fam → NT: | C111: =SUMIF(B4:B103,"Devolución Familia → NT",E4:E103)
A112: TOTAL INGRESOS: | C112: =SUM(C108:C111)
A113: EGRESOS:
A114: EGRESOS: | C114: =SUMIF(B4:B103,"Egreso NT",F4:F103)
A115: Egreso NT: | C115: =SUMIF(B4:B103,"Egreso NT",F4:F103)
A116: Egreso Familiar: | C116: =SUMIF(B4:B103,"Egreso Familiar",F4:F103)
A117: Préstamo NT → Fam: | C117: =SUMIF(B4:B103,"Préstamo NT → Familia",F4:F103)
A118: TOTAL EGRESOS: | C118: =SUM(C115:C117)
A120: SALDO PRÉSTAMO NT → FAM: | C120: =C117-C111
A121: (Prestado - Devuelto)

Sheet Febrero 2026
A1: 📊 CONTROL FINANCIERO - FEBRERO 2026
A3: TOTAL INGRESOS | D3: GASTOS PAGADOS | G3: GASTOS PENDIENTES | J3: BALANCE
A4: =D26+J12 | D4: =D65+I58 | G4: =D66+I59 | J4: =A4-D4-G4
A6: ⚠️ PRÉSTAMO NT → FAMILIA | D6: =SUMIF('Ing-Egr Febrero 2026'!B4:B103,"Préstamo NT → Familia",'Ing-Egr Febrero 2026'!F4:F103)-SUMIF('Ing-Egr Febrero 2026'!B4:B103,"Devolución Familia → NT",'Ing-Egr Febrero 2026'!E4:E103) | F6: Estado: | G6: =IF(D6=0,"🟢 SANO","🔴 FUGA") | I6: (Ideal = 0)
A8: 💵 INGRESOS FAMILIA | G8: 💵 INGRESOS NEUROTEA
A9: MARCO ITAIPU | C9: Fecha | D9: Monto | G9: Ingreso del Mes | J9: Monto
A10: Salario Mensual | D10: =SUMIFS('Ing-Egr Febrero 2026'!E4:E103,'Ing-Egr Febrero 2026'!B4:B103,"Ingreso Marco",'Ing-Egr Febrero 2026'!C4:C103,A10) | G10: (Suma desde pestaña Ing-Egr Febrero) | J10: =SUMIF('Ing-Egr Febrero 2026'!B4:B103,"Ingreso NT",'Ing-Egr Febrero 2026'!E4:E103)
A11: Vacaciones | D11: =SUMIFS('Ing-Egr Febrero 2026'!E4:E103,'Ing-Egr Febrero 2026'!B4:B103,"Ingreso Marco",'Ing-Egr Febrero 2026'!C4:C103,A11)
A12: Aguinaldo | D12: =SUMIFS('Ing-Egr Febrero 2026'!E4:E103,'Ing-Egr Febrero 2026'!B4:B103,"Ingreso Marco",'Ing-Egr Febrero 2026'!C4:C103,A12) | G12: ═══ TOTAL INGRESOS NT ═══ | J12: =J10
A13: Viático | D13: =SUMIFS('Ing-Egr Febrero 2026'!E4:E103,'Ing-Egr Febrero 2026'!B4:B103,"Ingreso Marco",'Ing-Egr Febrero 2026'!C4:C103,A13)
A14: Animador Bíblico | D14: =SUMIFS('Ing-Egr Febrero 2026'!E4:E103,'Ing-Egr Febrero 2026'!B4:B103,"Ingreso Marco",'Ing-Egr Febrero 2026'!C4:C103,A14)
A15: Otros Ocasionales | D15: =SUMIFS('Ing-Egr Febrero 2026'!E4:E103,'Ing-Egr Febrero 2026'!B4:B103,"Ingreso Marco",'Ing-Egr Febrero 2026'!C4:C103,A15) | I15: =J12
A16: TOTAL MARCO | D16: =SUM(D10:D15)
A17: CLARA | C17: Fecha | D17: Monto
A18: Honorarios Diarios | D18: =SUMIF('Ing-Egr Febrero 2026'!B4:B103,"Ingreso Clara",'Ing-Egr Febrero 2026'!E4:E103)
A19: TOTAL CLARA | D19: =D18
A20: DESDE NEUROTEA | D20: Monto
A21: Salario Admin Marco | D21: 0
A22: Ganancia NT → Familia | D22: 0
A23: Préstamo NT (automático) | D23: =D6
A24: TOTAL DESDE NT | D24: =SUM(D21:D23)
A26: ═══ TOTAL INGRESOS FAMILIA ═══ | D26: =D16+D19+D24
A28: 📉 GASTOS FAMILIARES | G28: 📉 GASTOS NEUROTEA
A29: Detalle | B29: Estado | C29: Monto | D29: Venc. | G29: Detalle | H29: Estado | I29: Monto | J29: Venc.
A30: ► GASTOS FIJOS ✏️ | G30: ► GASTOS FIJOS ✏️
A31: Salario Lili Doméstico | B31: Ninguno | G31: Alquiler 1 (Principal) | H31: Ninguno | I31: 0
A32: Salario Laura Doméstico | B32: Ninguno | G32: Alquiler 2 (Secundario) | H32: Ninguno | I32: 0
A33: Escuela Fabián y Brenda | B33: Ninguno | G33: Limpieza NeuroTEA | H33: Ninguno | I33: 0
A34: Robótica Niños | B34: Ninguno | G34: ► SUELDOS Y HONORARIOS ✏️
A35: ANDE Casa | B35: Ninguno | G35: Sueldo Aracely | H35: Ninguno | I35: 0
A36: Expensa Casa | B36: Ninguno | G36: Sueldo Fátima | H36: Ninguno | I36: 0
A37: Cajubi Marco | B37: Ninguno | G37: Honorario Contador | H37: Ninguno | I37: 0
A38: Mutual Marco | B38: Ninguno | G38: Salario Administrador | H38: Ninguno | I38: 0
A39: Ña Luisa | B39: Ninguno | G39: Honorario Mant. Sistema | H39: Ninguno | I39: 0
A40: Seguro Médico Papá y Mamá | B40: Ninguno | G40: ► TELEFONÍA E INTERNET ✏️
A41: ► CUOTAS Y PRÉSTAMOS ✏️ | G41: Celular Tigo NeuroTEA | H41: Ninguno | I41: 0
A42: Auto Laura Cuota | B42: Ninguno | G42: Celular Tigo Sistema | H42: Ninguno | I42: 0
A43: Coop. Universitaria Clara | B43: Ninguno | G43: WhatsFlow | H43: Ninguno | I43: 0
A44: Coomecipar Clara | B44: Ninguno | G44: Internet NeuroTEA | H44: Ninguno | I44: 0
A45: Tarjeta Cred. Coomecipar | B45: Ninguno | G45: ► IMPUESTOS ✏️
...

Sheet Ing-Egr Marzo 2026
A1: 📋 REGISTRO DE MOVIMIENTOS - MARZO 2026
A3: Fecha | B3: Tipo | C3: Categoría | D3: Descripción | E3: Ingreso | F3: Egreso | G3: Cuenta | H3: Notas
A104: TOTALES | E104: =SUM(E4:E103) | F104: =SUM(F4:F103)
A106: 📊 RESUMEN DEL MES
A107: INGRESOS: | C107: =SUMIF(B4:B103,"Ingreso NT",E4:E103)
A108: Ingreso NT: | C108: =SUMIF(B4:B103,"Ingreso NT",E4:E103)
A109: Ingreso Marco: | C109: =SUMIF(B4:B103,"Ingreso Marco",E4:E103)
A110: Ingreso Clara: | C110: =SUMIF(B4:B103,"Ingreso Clara",E4:E103)
A111: Devolución Fam → NT: | C111: =SUMIF(B4:B103,"Devolución Familia → NT",E4:E103)
A112: TOTAL INGRESOS: | C112: =SUM(C108:C111)
A113: EGRESOS:
A114: EGRESOS: | C114: =SUMIF(B4:B103,"Egreso NT",F4:F103)
A115: Egreso NT: | C115: =SUMIF(B4:B103,"Egreso NT",F4:F103)
A116: Egreso Familiar: | C116: =SUMIF(B4:B103,"Egreso Familiar",F4:F103)
A117: Préstamo NT → Fam: | C117: =SUMIF(B4:B103,"Préstamo NT → Familia",F4:F103)
A118: TOTAL EGRESOS: | C118: =SUM(C115:C117)
A120: SALDO PRÉSTAMO NT → FAM: | C120: =C117-C111
A121: (Prestado - Devuelto)

Sheet Marzo 2026
A1: 📊 CONTROL FINANCIERO - MARZO 2026
A3: TOTAL INGRESOS | D3: GASTOS PAGADOS | G3: GASTOS PENDIENTES | J3: BALANCE
A4: =D26+J12 | D4: =D65+I58 | G4: =D66+I59 | J4: =A4-D4-G4
A6: ⚠️ PRÉSTAMO NT → FAMILIA | D6: =SUMIF('Ing-Egr Marzo 2026'!B4:B103,"Préstamo NT → Familia",'Ing-Egr Marzo 2026'!F4:F103)-SUMIF('Ing-Egr Marzo 2026'!B4:B103,"Devolución Familia → NT",'Ing-Egr Marzo 2026'!E4:E103) | F6: Estado: | G6: =IF(D6=0,"🟢 SANO","🔴 FUGA") | I6: (Ideal = 0)
A8: 💵 INGRESOS FAMILIA | G8: 💵 INGRESOS NEUROTEA
A9: MARCO ITAIPU | C9: Fecha | D9: Monto | G9: Ingreso del Mes | J9: Monto
A10: Salario Mensual | D10: =SUMIFS('Ing-Egr Marzo 2026'!E4:E103,'Ing-Egr Marzo 2026'!B4:B103,"Ingreso Marco",'Ing-Egr Marzo 2026'!C4:C103,A10) | G10: (Suma desde pestaña Ing-Egr Marzo) | J10: =SUMIF('Ing-Egr Marzo 2026'!B4:B103,"Ingreso NT",'Ing-Egr Marzo 2026'!E4:E103)
A11: Vacaciones | D11: =SUMIFS('Ing-Egr Marzo 2026'!E4:E103,'Ing-Egr Marzo 2026'!B4:B103,"Ingreso Marco",'Ing-Egr Marzo 2026'!C4:C103,A11)
A12: Aguinaldo | D12: =SUMIFS('Ing-Egr Marzo 2026'!E4:E103,'Ing-Egr Marzo 2026'!B4:B103,"Ingreso Marco",'Ing-Egr Marzo 2026'!C4:C103,A12) | G12: ═══ TOTAL INGRESOS NT ═══ | J12: =J10
A13: Viático | D13: =SUMIFS('Ing-Egr Marzo 2026'!E4:E103,'Ing-Egr Marzo 2026'!B4:B103,"Ingreso Marco",'Ing-Egr Marzo 2026'!C4:C103,A13)
A14: Animador Bíblico | D14: =SUMIFS('Ing-Egr Marzo 2026'!E4:E103,'Ing-Egr Marzo 2026'!B4:B103,"Ingreso Marco",'Ing-Egr Marzo 2026'!C4:C103,A14)
A15: Otros Ocasionales | D15: =SUMIFS('Ing-Egr Marzo 2026'!E4:E103,'Ing-Egr Marzo 2026'!B4:B103,"Ingreso Marco",'Ing-Egr Marzo 2026'!C4:C103,A15) | I15: =J12
A16: TOTAL MARCO | D16: =SUM(D10:D15)
A17: CLARA | C17: Fecha | D17: Monto
A18: Honorarios Diarios | D18: =SUMIF('Ing-Egr Marzo 2026'!B4:B103,"Ingreso Clara",'Ing-Egr Marzo 2026'!E4:E103)
A19: TOTAL CLARA | D19: =D18
A20: DESDE NEUROTEA | D20: Monto
A21: Salario Admin Marco | D21: 0
A22: Ganancia NT → Familia | D22: 0
A23: Préstamo NT (automático) | D23: =D6
A24: TOTAL DESDE NT | D24: =SUM(D21:D23)
A26: ═══ TOTAL INGRESOS FAMILIA ═══ | D26: =D16+D19+D24
A28: 📉 GASTOS FAMILIARES | G28: 📉 GASTOS NEUROTEA
A29: Detalle | B29: Estado | C29: Monto | D29: Venc. | G29: Detalle | H29: Estado | I29: Monto | J29: Venc.
A30: ► GASTOS FIJOS ✏️ | G30: ► GASTOS FIJOS ✏️
A31: Salario Lili Doméstico | B31: Ninguno | G31: Alquiler 1 (Principal) | H31: Ninguno | I31: 0
A32: Salario Laura Doméstico | B32: Ninguno | G32: Alquiler 2 (Secundario) | H32: Ninguno | I32: 0
A33: Escuela Fabián y Brenda | B33: Ninguno | G33: Limpieza NeuroTEA | H33: Ninguno | I33: 0
A34: Robótica Niños | B34: Ninguno | G34: ► SUELDOS Y HONORARIOS ✏️
A35: ANDE Casa | B35: Ninguno | G35: Sueldo Aracely | H35: Ninguno | I35: 0
A36: Expensa Casa | B36: Ninguno | G36: Sueldo Fátima | H36: Ninguno | I36: 0
A37: Cajubi Marco | B37: Ninguno | G37: Honorario Contador | H37: Ninguno | I37: 0
A38: Mutual Marco | B38: Ninguno | G38: Salario Administrador | H38: Ninguno | I38: 0
A39: Ña Luisa | B39: Ninguno | G39: Honorario Mant. Sistema | H39: Ninguno | I39: 0
A40: Seguro Médico Papá y Mamá | B40: Ninguno | G40: ► TELEFONÍA E INTERNET ✏️
A41: ► CUOTAS Y PRÉSTAMOS ✏️ | G41: Celular Tigo NeuroTEA | H41: Ninguno | I41: 0
A42: Auto Laura Cuota | B42: Ninguno | G42: Celular Tigo Sistema | H42: Ninguno | I42: 0
A43: Coop. Universitaria Clara | B43: Ninguno | G43: WhatsFlow | H43: Ninguno | I43: 0
A44: Coomecipar Clara | B44: Ninguno | G44: Internet NeuroTEA | H44: Ninguno | I44: 0
A45: Tarjeta Cred. Coomecipar | B45: Ninguno | G45: ► IMPUESTOS ✏️
...

Sheet Ing-Egr Abril 2026
A1: 📋 REGISTRO DE MOVIMIENTOS - ABRIL 2026
A3: Fecha | B3: Tipo | C3: Categoría | D3: Descripción | E3: Ingreso | F3: Egreso | G3: Cuenta | H3: Notas
A104: TOTALES | E104: =SUM(E4:E103) | F104: =SUM(F4:F103)
A106: 📊 RESUMEN DEL MES
A107: INGRESOS: | C107: =SUMIF(B4:B103,"Ingreso NT",E4:E103)
A108: Ingreso NT: | C108: =SUMIF(B4:B103,"Ingreso NT",E4:E103)
A109: Ingreso Marco: | C109: =SUMIF(B4:B103,"Ingreso Marco",E4:E103)
A110: Ingreso Clara: | C110: =SUMIF(B4:B103,"Ingreso Clara",E4:E103)
A111: Devolución Fam → NT: | C111: =SUMIF(B4:B103,"Devolución Familia → NT",E4:E103)
A112: TOTAL INGRESOS: | C112: =SUM(C108:C111)
A113: EGRESOS:
A114: EGRESOS: | C114: =SUMIF(B4:B103,"Egreso NT",F4:F103)
A115: Egreso NT: | C115: =SUMIF(B4:B103,"Egreso NT",F4:F103)
A116: Egreso Familiar: | C116: =SUMIF(B4:B103,"Egreso Familiar",F4:F103)
A117: Préstamo NT → Fam: | C117: =SUMIF(B4:B103,"Préstamo NT → Familia",F4:F103)
A118: TOTAL EGRESOS: | C118: =SUM(C115:C117)
A120: SALDO PRÉSTAMO NT → FAM: | C120: =C117-C111
A121: (Prestado - Devuelto)

Sheet Abril 2026
A1: 📊 CONTROL FINANCIERO - ABRIL 2026
A3: TOTAL INGRESOS | D3: GASTOS PAGADOS | G3: GASTOS PENDIENTES | J3: BALANCE
A4: =D26+J12 | D4: =D65+I58 | G4: =D66+I59 | J4: =A4-D4-G4
A6: ⚠️ PRÉSTAMO NT → FAMILIA | D6: =SUMIF('Ing-Egr Abril 2026'!B4:B103,"Préstamo NT → Familia",'Ing-Egr Abril 2026'!F4:F103)-SUMIF('Ing-Egr Abril 2026'!B4:B103,"Devolución Familia → NT",'Ing-Egr Abril 2026'!E4:E103) | F6: Estado: | G6: =IF(D6=0,"🟢 SANO","🔴 FUGA") | I6: (Ideal = 0)
A8: 💵 INGRESOS FAMILIA | G8: 💵 INGRESOS NEUROTEA
A9: MARCO ITAIPU | C9: Fecha | D9: Monto | G9: Ingreso del Mes | J9: Monto
A10: Salario Mensual | D10: =SUMIFS('Ing-Egr Abril 2026'!E4:E103,'Ing-Egr Abril 2026'!B4:B103,"Ingreso Marco",'Ing-Egr Abril 2026'!C4:C103,A10) | G10: (Suma desde pestaña Ing-Egr Abril) | J10: =SUMIF('Ing-Egr Abril 2026'!B4:B103,"Ingreso NT",'Ing-Egr Abril 2026'!E4:E103)
A11: Vacaciones | D11: =SUMIFS('Ing-Egr Abril 2026'!E4:E103,'Ing-Egr Abril 2026'!B4:B103,"Ingreso Marco",'Ing-Egr Abril 2026'!C4:C103,A11)
A12: Aguinaldo | D12: =SUMIFS('Ing-Egr Abril 2026'!E4:E103,'Ing-Egr Abril 2026'!B4:B103,"Ingreso Marco",'Ing-Egr Abril 2026'!C4:C103,A12) | G12: ═══ TOTAL INGRESOS NT ═══ | J12: =J10
A13: Viático | D13: =SUMIFS('Ing-Egr Abril 2026'!E4:E103,'Ing-Egr Abril 2026'!B4:B103,"Ingreso Marco",'Ing-Egr Abril 2026'!C4:C103,A13)
A14: Animador Bíblico | D14: =SUMIFS('Ing-Egr Abril 2026'!E4:E103,'Ing-Egr Abril 2026'!B4:B103,"Ingreso Marco",'Ing-Egr Abril 2026'!C4:C103,A14)
A15: Otros Ocasionales | D15: =SUMIFS('Ing-Egr Abril 2026'!E4:E103,'Ing-Egr Abril 2026'!B4:B103,"Ingreso Marco",'Ing-Egr Abril 2026'!C4:C103,A15) | I15: =J12
A16: TOTAL MARCO | D16: =SUM(D10:D15)
A17: CLARA | C17: Fecha | D17: Monto
A18: Honorarios Diarios | D18: =SUMIF('Ing-Egr Abril 2026'!B4:B103,"Ingreso Clara",'Ing-Egr Abril 2026'!E4:E103)
A19: TOTAL CLARA | D19: =D18
A20: DESDE NEUROTEA | D20: Monto
A21: Salario Admin Marco | D21: 0
A22: Ganancia NT → Familia | D22: 0
A23: Préstamo NT (automático) | D23: =D6
A24: TOTAL DESDE NT | D24: =SUM(D21:D23)
A26: ═══ TOTAL INGRESOS FAMILIA ═══ | D26: =D16+D19+D24
A28: 📉 GASTOS FAMILIARES | G28: 📉 GASTOS NEUROTEA
A29: Detalle | B29: Estado | C29: Monto | D29: Venc. | G29: Detalle | H29: Estado | I29: Monto | J29: Venc.
A30: ► GASTOS FIJOS ✏️ | G30: ► GASTOS FIJOS ✏️
A31: Salario Lili Doméstico | B31: Ninguno | G31: Alquiler 1 (Principal) | H31: Ninguno | I31: 0
A32: Salario Laura Doméstico | B32: Ninguno | G32: Alquiler 2 (Secundario) | H32: Ninguno | I32: 0
A33: Escuela Fabián y Brenda | B33: Ninguno | G33: Limpieza NeuroTEA | H33: Ninguno | I33: 0
A34: Robótica Niños | B34: Ninguno | G34: ► SUELDOS Y HONORARIOS ✏️
A35: ANDE Casa | B35: Ninguno | G35: Sueldo Aracely | H35: Ninguno | I35: 0
A36: Expensa Casa | B36: Ninguno | G36: Sueldo Fátima | H36: Ninguno | I36: 0
A37: Cajubi Marco | B37: Ninguno | G37: Honorario Contador | H37: Ninguno | I37: 0
A38: Mutual Marco | B38: Ninguno | G38: Salario Administrador | H38: Ninguno | I38: 0
A39: Ña Luisa | B39: Ninguno | G39: Honorario Mant. Sistema | H39: Ninguno | I39: 0
A40: Seguro Médico Papá y Mamá | B40: Ninguno | G40: ► TELEFONÍA E INTERNET ✏️
A41: ► CUOTAS Y PRÉSTAMOS ✏️ | G41: Celular Tigo NeuroTEA | H41: Ninguno | I41: 0
A42: Auto Laura Cuota | B42: Ninguno | G42: Celular Tigo Sistema | H42: Ninguno | I42: 0
A43: Coop. Universitaria Clara | B43: Ninguno | G43: WhatsFlow | H43: Ninguno | I43: 0
A44: Coomecipar Clara | B44: Ninguno | G44: Internet NeuroTEA | H44: Ninguno | I44: 0
A45: Tarjeta Cred. Coomecipar | B45: Ninguno | G45: ► IMPUESTOS ✏️
...

Sheet Ing-Egr Mayo 2026
A1: 📋 REGISTRO DE MOVIMIENTOS - MAYO 2026
A3: Fecha | B3: Tipo | C3: Categoría | D3: Descripción | E3: Ingreso | F3: Egreso | G3: Cuenta | H3: Notas
A104: TOTALES | E104: =SUM(E4:E103) | F104: =SUM(F4:F103)
A106: 📊 RESUMEN DEL MES
A107: INGRESOS: | C107: =SUMIF(B4:B103,"Ingreso NT",E4:E103)
A108: Ingreso NT: | C108: =SUMIF(B4:B103,"Ingreso NT",E4:E103)
A109: Ingreso Marco: | C109: =SUMIF(B4:B103,"Ingreso Marco",E4:E103)
A110: Ingreso Clara: | C110: =SUMIF(B4:B103,"Ingreso Clara",E4:E103)
A111: Devolución Fam → NT: | C111: =SUMIF(B4:B103,"Devolución Familia → NT",E4:E103)
A112: TOTAL INGRESOS: | C112: =SUM(C108:C111)
A113: EGRESOS:
A114: EGRESOS: | C114: =SUMIF(B4:B103,"Egreso NT",F4:F103)
A115: Egreso NT: | C115: =SUMIF(B4:B103,"Egreso NT",F4:F103)
A116: Egreso Familiar: | C116: =SUMIF(B4:B103,"Egreso Familiar",F4:F103)
A117: Préstamo NT → Fam: | C117: =SUMIF(B4:B103,"Préstamo NT → Familia",F4:F103)
A118: TOTAL EGRESOS: | C118: =SUM(C115:C117)
A120: SALDO PRÉSTAMO NT → FAM: | C120: =C117-C111
A121: (Prestado - Devuelto)

Sheet Mayo 2026
A1: 📊 CONTROL FINANCIERO - MAYO 2026
A3: TOTAL INGRESOS | D3: GASTOS PAGADOS | G3: GASTOS PENDIENTES | J3: BALANCE
A4: =D26+J12 | D4: =D65+I58 | G4: =D66+I59 | J4: =A4-D4-G4
A6: ⚠️ PRÉSTAMO NT → FAMILIA | D6: =SUMIF('Ing-Egr Mayo 2026'!B4:B103,"Préstamo NT → Familia",'Ing-Egr Mayo 2026'!F4:F103)-SUMIF('Ing-Egr Mayo 2026'!B4:B103,"Devolución Familia → NT",'Ing-Egr Mayo 2026'!E4:E103) | F6: Estado: | G6: =IF(D6=0,"🟢 SANO","🔴 FUGA") | I6: (Ideal = 0)
A8: 💵 INGRESOS FAMILIA | G8: 💵 INGRESOS NEUROTEA
A9: MARCO ITAIPU | C9: Fecha | D9: Monto | G9: Ingreso del Mes | J9: Monto
A10: Salario Mensual | D10: =SUMIFS('Ing-Egr Mayo 2026'!E4:E103,'Ing-Egr Mayo 2026'!B4:B103,"Ingreso Marco",'Ing-Egr Mayo 2026'!C4:C103,A10) | G10: (Suma desde pestaña Ing-Egr Mayo) | J10: =SUMIF('Ing-Egr Mayo 2026'!B4:B103,"Ingreso NT",'Ing-Egr Mayo 2026'!E4:E103)
A11: Vacaciones | D11: =SUMIFS('Ing-Egr Mayo 2026'!E4:E103,'Ing-Egr Mayo 2026'!B4:B103,"Ingreso Marco",'Ing-Egr Mayo 2026'!C4:C103,A11)
A12: Aguinaldo | D12: =SUMIFS('Ing-Egr Mayo 2026'!E4:E103,'Ing-Egr Mayo 2026'!B4:B103,"Ingreso Marco",'Ing-Egr Mayo 2026'!C4:C103,A12) | G12: ═══ TOTAL INGRESOS NT ═══ | J12: =J10
A13: Viático | D13: =SUMIFS('Ing-Egr Mayo 2026'!E4:E103,'Ing-Egr Mayo 2026'!B4:B103,"Ingreso Marco",'Ing-Egr Mayo 2026'!C4:C103,A13)
A14: Animador Bíblico | D14: =SUMIFS('Ing-Egr Mayo 2026'!E4:E103,'Ing-Egr Mayo 2026'!B4:B103,"Ingreso Marco",'Ing-Egr Mayo 2026'!C4:C103,A14)
A15: Otros Ocasionales | D15: =SUMIFS('Ing-Egr Mayo 2026'!E4:E103,'Ing-Egr Mayo 2026'!B4:B103,"Ingreso Marco",'Ing-Egr Mayo 2026'!C4:C103,A15) | I15: =J12
A16: TOTAL MARCO | D16: =SUM(D10:D15)
A17: CLARA | C17: Fecha | D17: Monto
A18: Honorarios Diarios | D18: =SUMIF('Ing-Egr Mayo 2026'!B4:B103,"Ingreso Clara",'Ing-Egr Mayo 2026'!E4:E103)
A19: TOTAL CLARA | D19: =D18
A20: DESDE NEUROTEA | D20: Monto
A21: Salario Admin Marco | D21: 0
A22: Ganancia NT → Familia | D22: 0
A23: Préstamo NT (automático) | D23: =D6
A24: TOTAL DESDE NT | D24: =SUM(D21:D23)
A26: ═══ TOTAL INGRESOS FAMILIA ═══ | D26: =D16+D19+D24
A28: 📉 GASTOS FAMILIARES | G28: 📉 GASTOS NEUROTEA
A29: Detalle | B29: Estado | C29: Monto | D29: Venc. | G29: Detalle | H29: Estado | I29: Monto | J29: Venc.
A30: ► GASTOS FIJOS ✏️ | G30: ► GASTOS FIJOS ✏️
A31: Salario Lili Doméstico | B31: Ninguno | G31: Alquiler 1 (Principal) | H31: Ninguno | I31: 0
A32: Salario Laura Doméstico | B32: Ninguno | G32: Alquiler 2 (Secundario) | H32: Ninguno | I32: 0
A33: Escuela Fabián y Brenda | B33: Ninguno | G33: Limpieza NeuroTEA | H33: Ninguno | I33: 0
A34: Robótica Niños | B34: Ninguno | G34: ► SUELDOS Y HONORARIOS ✏️
A35: ANDE Casa | B35: Ninguno | G35: Sueldo Aracely | H35: Ninguno | I35: 0
A36: Expensa Casa | B36: Ninguno | G36: Sueldo Fátima | H36: Ninguno | I36: 0
A37: Cajubi Marco | B37: Ninguno | G37: Honorario Contador | H37: Ninguno | I37: 0
A38: Mutual Marco | B38: Ninguno | G38: Salario Administrador | H38: Ninguno | I38: 0
A39: Ña Luisa | B39: Ninguno | G39: Honorario Mant. Sistema | H39: Ninguno | I39: 0
A40: Seguro Médico Papá y Mamá | B40: Ninguno | G40: ► TELEFONÍA E INTERNET ✏️
A41: ► CUOTAS Y PRÉSTAMOS ✏️ | G41: Celular Tigo NeuroTEA | H41: Ninguno | I41: 0
A42: Auto Laura Cuota | B42: Ninguno | G42: Celular Tigo Sistema | H42: Ninguno | I42: 0
A43: Coop. Universitaria Clara | B43: Ninguno | G43: WhatsFlow | H43: Ninguno | I43: 0
A44: Coomecipar Clara | B44: Ninguno | G44: Internet NeuroTEA | H44: Ninguno | I44: 0
A45: Tarjeta Cred. Coomecipar | B45: Ninguno | G45: ► IMPUESTOS ✏️
...

Sheet Ing-Egr Junio 2026
A1: 📋 REGISTRO DE MOVIMIENTOS - JUNIO 2026
A3: Fecha | B3: Tipo | C3: Categoría | D3: Descripción | E3: Ingreso | F3: Egreso | G3: Cuenta | H3: Notas
A104: TOTALES | E104: =SUM(E4:E103) | F104: =SUM(F4:F103)
A106: 📊 RESUMEN DEL MES
A107: INGRESOS: | C107: =SUMIF(B4:B103,"Ingreso NT",E4:E103)
A108: Ingreso NT: | C108: =SUMIF(B4:B103,"Ingreso NT",E4:E103)
A109: Ingreso Marco: | C109: =SUMIF(B4:B103,"Ingreso Marco",E4:E103)
A110: Ingreso Clara: | C110: =SUMIF(B4:B103,"Ingreso Clara",E4:E103)
A111: Devolución Fam → NT: | C111: =SUMIF(B4:B103,"Devolución Familia → NT",E4:E103)
A112: TOTAL INGRESOS: | C112: =SUM(C108:C111)
A113: EGRESOS:
A114: EGRESOS: | C114: =SUMIF(B4:B103,"Egreso NT",F4:F103)
A115: Egreso NT: | C115: =SUMIF(B4:B103,"Egreso NT",F4:F103)
A116: Egreso Familiar: | C116: =SUMIF(B4:B103,"Egreso Familiar",F4:F103)
A117: Préstamo NT → Fam: | C117: =SUMIF(B4:B103,"Préstamo NT → Familia",F4:F103)
A118: TOTAL EGRESOS: | C118: =SUM(C115:C117)
A120: SALDO PRÉSTAMO NT → FAM: | C120: =C117-C111
A121: (Prestado - Devuelto)

Sheet Junio 2026
A1: 📊 CONTROL FINANCIERO - JUNIO 2026
A3: TOTAL INGRESOS | D3: GASTOS PAGADOS | G3: GASTOS PENDIENTES | J3: BALANCE
A4: =D26+J12 | D4: =D65+I58 | G4: =D66+I59 | J4: =A4-D4-G4
A6: ⚠️ PRÉSTAMO NT → FAMILIA | D6: =SUMIF('Ing-Egr Junio 2026'!B4:B103,"Préstamo NT → Familia",'Ing-Egr Junio 2026'!F4:F103)-SUMIF('Ing-Egr Junio 2026'!B4:B103,"Devolución Familia → NT",'Ing-Egr Junio 2026'!E4:E103) | F6: Estado: | G6: =IF(D6=0,"🟢 SANO","🔴 FUGA") | I6: (Ideal = 0)
A8: 💵 INGRESOS FAMILIA | G8: 💵 INGRESOS NEUROTEA
A9: MARCO ITAIPU | C9: Fecha | D9: Monto | G9: Ingreso del Mes | J9: Monto
A10: Salario Mensual | D10: =SUMIFS('Ing-Egr Junio 2026'!E4:E103,'Ing-Egr Junio 2026'!B4:B103,"Ingreso Marco",'Ing-Egr Junio 2026'!C4:C103,A10) | G10: (Suma desde pestaña Ing-Egr Junio) | J10: =SUMIF('Ing-Egr Junio 2026'!B4:B103,"Ingreso NT",'Ing-Egr Junio 2026'!E4:E103)
A11: Vacaciones | D11: =SUMIFS('Ing-Egr Junio 2026'!E4:E103,'Ing-Egr Junio 2026'!B4:B103,"Ingreso Marco",'Ing-Egr Junio 2026'!C4:C103,A11)
A12: Aguinaldo | D12: =SUMIFS('Ing-Egr Junio 2026'!E4:E103,'Ing-Egr Junio 2026'!B4:B103,"Ingreso Marco",'Ing-Egr Junio 2026'!C4:C103,A12) | G12: ═══ TOTAL INGRESOS NT ═══ | J12: =J10
A13: Viático | D13: =SUMIFS('Ing-Egr Junio 2026'!E4:E103,'Ing-Egr Junio 2026'!B4:B103,"Ingreso Marco",'Ing-Egr Junio 2026'!C4:C103,A13)
A14: Animador Bíblico | D14: =SUMIFS('Ing-Egr Junio 2026'!E4:E103,'Ing-Egr Junio 2026'!B4:B103,"Ingreso Marco",'Ing-Egr Junio 2026'!C4:C103,A14)
A15: Otros Ocasionales | D15: =SUMIFS('Ing-Egr Junio 2026'!E4:E103,'Ing-Egr Junio 2026'!B4:B103,"Ingreso Marco",'Ing-Egr Junio 2026'!C4:C103,A15) | I15: =J12
A16: TOTAL MARCO | D16: =SUM(D10:D15)
A17: CLARA | C17: Fecha | D17: Monto
A18: Honorarios Diarios | D18: =SUMIF('Ing-Egr Junio 2026'!B4:B103,"Ingreso Clara",'Ing-Egr Junio 2026'!E4:E103)
A19: TOTAL CLARA | D19: =D18
A20: DESDE NEUROTEA | D20: Monto
A21: Salario Admin Marco | D21: 0
A22: Ganancia NT → Familia | D22: 0
A23: Préstamo NT (automático) | D23: =D6
A24: TOTAL DESDE NT | D24: =SUM(D21:D23)
A26: ═══ TOTAL INGRESOS FAMILIA ═══ | D26: =D16+D19+D24
A28: 📉 GASTOS FAMILIARES | G28: 📉 GASTOS NEUROTEA
A29: Detalle | B29: Estado | C29: Monto | D29: Venc. | G29: Detalle | H29: Estado | I29: Monto | J29: Venc.
A30: ► GASTOS FIJOS ✏️ | G30: ► GASTOS FIJOS ✏️
A31: Salario Lili Doméstico | B31: Ninguno | G31: Alquiler 1 (Principal) | H31: Ninguno | I31: 0
A32: Salario Laura Doméstico | B32: Ninguno | G32: Alquiler 2 (Secundario) | H32: Ninguno | I32: 0
A33: Escuela Fabián y Brenda | B33: Ninguno | G33: Limpieza NeuroTEA | H33: Ninguno | I33: 0
A34: Robótica Niños | B34: Ninguno | G34: ► SUELDOS Y HONORARIOS ✏️
A35: ANDE Casa | B35: Ninguno | G35: Sueldo Aracely | H35: Ninguno | I35: 0
A36: Expensa Casa | B36: Ninguno | G36: Sueldo Fátima | H36: Ninguno | I36: 0
A37: Cajubi Marco | B37: Ninguno | G37: Honorario Contador | H37: Ninguno | I37: 0
A38: Mutual Marco | B38: Ninguno | G38: Salario Administrador | H38: Ninguno | I38: 0
A39: Ña Luisa | B39: Ninguno | G39: Honorario Mant. Sistema | H39: Ninguno | I39: 0
A40: Seguro Médico Papá y Mamá | B40: Ninguno | G40: ► TELEFONÍA E INTERNET ✏️
A41: ► CUOTAS Y PRÉSTAMOS ✏️ | G41: Celular Tigo NeuroTEA | H41: Ninguno | I41: 0
A42: Auto Laura Cuota | B42: Ninguno | G42: Celular Tigo Sistema | H42: Ninguno | I42: 0
A43: Coop. Universitaria Clara | B43: Ninguno | G43: WhatsFlow | H43: Ninguno | I43: 0
A44: Coomecipar Clara | B44: Ninguno | G44: Internet NeuroTEA | H44: Ninguno | I44: 0
A45: Tarjeta Cred. Coomecipar | B45: Ninguno | G45: ► IMPUESTOS ✏️
...

Sheet Ing-Egr Julio 2026
A1: 📋 REGISTRO DE MOVIMIENTOS - JULIO 2026
A3: Fecha | B3: Tipo | C3: Categoría | D3: Descripción | E3: Ingreso | F3: Egreso | G3: Cuenta | H3: Notas
A104: TOTALES | E104: =SUM(E4:E103) | F104: =SUM(F4:F103)
A106: 📊 RESUMEN DEL MES
A107: INGRESOS: | C107: =SUMIF(B4:B103,"Ingreso NT",E4:E103)
A108: Ingreso NT: | C108: =SUMIF(B4:B103,"Ingreso NT",E4:E103)
A109: Ingreso Marco: | C109: =SUMIF(B4:B103,"Ingreso Marco",E4:E103)
A110: Ingreso Clara: | C110: =SUMIF(B4:B103,"Ingreso Clara",E4:E103)
A111: Devolución Fam → NT: | C111: =SUMIF(B4:B103,"Devolución Familia → NT",E4:E103)
A112: TOTAL INGRESOS: | C112: =SUM(C108:C111)
A113: EGRESOS:
A114: EGRESOS: | C114: =SUMIF(B4:B103,"Egreso NT",F4:F103)
A115: Egreso NT: | C115: =SUMIF(B4:B103,"Egreso NT",F4:F103)
A116: Egreso Familiar: | C116: =SUMIF(B4:B103,"Egreso Familiar",F4:F103)
A117: Préstamo NT → Fam: | C117: =SUMIF(B4:B103,"Préstamo NT → Familia",F4:F103)
A118: TOTAL EGRESOS: | C118: =SUM(C115:C117)
A120: SALDO PRÉSTAMO NT → FAM: | C120: =C117-C111
A121: (Prestado - Devuelto)

Sheet Julio 2026
A1: 📊 CONTROL FINANCIERO - JULIO 2026
A3: TOTAL INGRESOS | D3: GASTOS PAGADOS | G3: GASTOS PENDIENTES | J3: BALANCE
A4: =D26+J12 | D4: =D65+I58 | G4: =D66+I59 | J4: =A4-D4-G4
A6: ⚠️ PRÉSTAMO NT → FAMILIA | D6: =SUMIF('Ing-Egr Julio 2026'!B4:B103,"Préstamo NT → Familia",'Ing-Egr Julio 2026'!F4:F103)-SUMIF('Ing-Egr Julio 2026'!B4:B103,"Devolución Familia → NT",'Ing-Egr Julio 2026'!E4:E103) | F6: Estado: | G6: =IF(D6=0,"🟢 SANO","🔴 FUGA") | I6: (Ideal = 0)
A8: 💵 INGRESOS FAMILIA | G8: 💵 INGRESOS NEUROTEA
A9: MARCO ITAIPU | C9: Fecha | D9: Monto | G9: Ingreso del Mes | J9: Monto
A10: Salario Mensual | D10: =SUMIFS('Ing-Egr Julio 2026'!E4:E103,'Ing-Egr Julio 2026'!B4:B103,"Ingreso Marco",'Ing-Egr Julio 2026'!C4:C103,A10) | G10: (Suma desde pestaña Ing-Egr Julio) | J10: =SUMIF('Ing-Egr Julio 2026'!B4:B103,"Ingreso NT",'Ing-Egr Julio 2026'!E4:E103)
A11: Vacaciones | D11: =SUMIFS('Ing-Egr Julio 2026'!E4:E103,'Ing-Egr Julio 2026'!B4:B103,"Ingreso Marco",'Ing-Egr Julio 2026'!C4:C103,A11)
A12: Aguinaldo | D12: =SUMIFS('Ing-Egr Julio 2026'!E4:E103,'Ing-Egr Julio 2026'!B4:B103,"Ingreso Marco",'Ing-Egr Julio 2026'!C4:C103,A12) | G12: ═══ TOTAL INGRESOS NT ═══ | J12: =J10
A13: Viático | D13: =SUMIFS('Ing-Egr Julio 2026'!E4:E103,'Ing-Egr Julio 2026'!B4:B103,"Ingreso Marco",'Ing-Egr Julio 2026'!C4:C103,A13)
A14: Animador Bíblico | D14: =SUMIFS('Ing-Egr Julio 2026'!E4:E103,'Ing-Egr Julio 2026'!B4:B103,"Ingreso Marco",'Ing-Egr Julio 2026'!C4:C103,A14)
A15: Otros Ocasionales | D15: =SUMIFS('Ing-Egr Julio 2026'!E4:E103,'Ing-Egr Julio 2026'!B4:B103,"Ingreso Marco",'Ing-Egr Julio 2026'!C4:C103,A15) | I15: =J12
A16: TOTAL MARCO | D16: =SUM(D10:D15)
A17: CLARA | C17: Fecha | D17: Monto
A18: Honorarios Diarios | D18: =SUMIF('Ing-Egr Julio 2026'!B4:B103,"Ingreso Clara",'Ing-Egr Julio 2026'!E4:E103)
A19: TOTAL CLARA | D19: =D18
A20: DESDE NEUROTEA | D20: Monto
A21: Salario Admin Marco | D21: 0
A22: Ganancia NT → Familia | D22: 0
A23: Préstamo NT (automático) | D23: =D6
A24: TOTAL DESDE NT | D24: =SUM(D21:D23)
A26: ═══ TOTAL INGRESOS FAMILIA ═══ | D26: =D16+D19+D24
A28: 📉 GASTOS FAMILIARES | G28: 📉 GASTOS NEUROTEA
A29: Detalle | B29: Estado | C29: Monto | D29: Venc. | G29: Detalle | H29: Estado | I29: Monto | J29: Venc.
A30: ► GASTOS FIJOS ✏️ | G30: ► GASTOS FIJOS ✏️
A31: Salario Lili Doméstico | B31: Ninguno | G31: Alquiler 1 (Principal) | H31: Ninguno | I31: 0
A32: Salario Laura Doméstico | B32: Ninguno | G32: Alquiler 2 (Secundario) | H32: Ninguno | I32: 0
A33: Escuela Fabián y Brenda | B33: Ninguno | G33: Limpieza NeuroTEA | H33: Ninguno | I33: 0
A34: Robótica Niños | B34: Ninguno | G34: ► SUELDOS Y HONORARIOS ✏️
A35: ANDE Casa | B35: Ninguno | G35: Sueldo Aracely | H35: Ninguno | I35: 0
A36: Expensa Casa | B36: Ninguno | G36: Sueldo Fátima | H36: Ninguno | I36: 0
A37: Cajubi Marco | B37: Ninguno | G37: Honorario Contador | H37: Ninguno | I37: 0
A38: Mutual Marco | B38: Ninguno | G38: Salario Administrador | H38: Ninguno | I38: 0
A39: Ña Luisa | B39: Ninguno | G39: Honorario Mant. Sistema | H39: Ninguno | I39: 0
A40: Seguro Médico Papá y Mamá | B40: Ninguno | G40: ► TELEFONÍA E INTERNET ✏️
A41: ► CUOTAS Y PRÉSTAMOS ✏️ | G41: Celular Tigo NeuroTEA | H41: Ninguno | I41: 0
A42: Auto Laura Cuota | B42: Ninguno | G42: Celular Tigo Sistema | H42: Ninguno | I42: 0
A43: Coop. Universitaria Clara | B43: Ninguno | G43: WhatsFlow | H43: Ninguno | I43: 0
A44: Coomecipar Clara | B44: Ninguno | G44: Internet NeuroTEA | H44: Ninguno | I44: 0
A45: Tarjeta Cred. Coomecipar | B45: Ninguno | G45: ► IMPUESTOS ✏️
...

Sheet Ing-Egr Agosto 2026
A1: 📋 REGISTRO DE MOVIMIENTOS - AGOSTO 2026
A3: Fecha | B3: Tipo | C3: Categoría | D3: Descripción | E3: Ingreso | F3: Egreso | G3: Cuenta | H3: Notas
A104: TOTALES | E104: =SUM(E4:E103) | F104: =SUM(F4:F103)
A106: 📊 RESUMEN DEL MES
A107: INGRESOS: | C107: =SUMIF(B4:B103,"Ingreso NT",E4:E103)
A108: Ingreso NT: | C108: =SUMIF(B4:B103,"Ingreso NT",E4:E103)
A109: Ingreso Marco: | C109: =SUMIF(B4:B103,"Ingreso Marco",E4:E103)
A110: Ingreso Clara: | C110: =SUMIF(B4:B103,"Ingreso Clara",E4:E103)
A111: Devolución Fam → NT: | C111: =SUMIF(B4:B103,"Devolución Familia → NT",E4:E103)
A112: TOTAL INGRESOS: | C112: =SUM(C108:C111)
A113: EGRESOS:
A114: EGRESOS: | C114: =SUMIF(B4:B103,"Egreso NT",F4:F103)
A115: Egreso NT: | C115: =SUMIF(B4:B103,"Egreso NT",F4:F103)
A116: Egreso Familiar: | C116: =SUMIF(B4:B103,"Egreso Familiar",F4:F103)
A117: Préstamo NT → Fam: | C117: =SUMIF(B4:B103,"Préstamo NT → Familia",F4:F103)
A118: TOTAL EGRESOS: | C118: =SUM(C115:C117)
A120: SALDO PRÉSTAMO NT → FAM: | C120: =C117-C111
A121: (Prestado - Devuelto)

Sheet Agosto 2026
A1: 📊 CONTROL FINANCIERO - AGOSTO 2026
A3: TOTAL INGRESOS | D3: GASTOS PAGADOS | G3: GASTOS PENDIENTES | J3: BALANCE
A4: =D26+J12 | D4: =D65+I58 | G4: =D66+I59 | J4: =A4-D4-G4
A6: ⚠️ PRÉSTAMO NT → FAMILIA | D6: =SUMIF('Ing-Egr Agosto 2026'!B4:B103,"Préstamo NT → Familia",'Ing-Egr Agosto 2026'!F4:F103)-SUMIF('Ing-Egr Agosto 2026'!B4:B103,"Devolución Familia → NT",'Ing-Egr Agosto 2026'!E4:E103) | F6: Estado: | G6: =IF(D6=0,"🟢 SANO","🔴 FUGA") | I6: (Ideal = 0)
A8: 💵 INGRESOS FAMILIA | G8: 💵 INGRESOS NEUROTEA
A9: MARCO ITAIPU | C9: Fecha | D9: Monto | G9: Ingreso del Mes | J9: Monto
A10: Salario Mensual | D10: =SUMIFS('Ing-Egr Agosto 2026'!E4:E103,'Ing-Egr Agosto 2026'!B4:B103,"Ingreso Marco",'Ing-Egr Agosto 2026'!C4:C103,A10) | G10: (Suma desde pestaña Ing-Egr Agosto) | J10: =SUMIF('Ing-Egr Agosto 2026'!B4:B103,"Ingreso NT",'Ing-Egr Agosto 2026'!E4:E103)
A11: Vacaciones | D11: =SUMIFS('Ing-Egr Agosto 2026'!E4:E103,'Ing-Egr Agosto 2026'!B4:B103,"Ingreso Marco",'Ing-Egr Agosto 2026'!C4:C103,A11)
A12: Aguinaldo | D12: =SUMIFS('Ing-Egr Agosto 2026'!E4:E103,'Ing-Egr Agosto 2026'!B4:B103,"Ingreso Marco",'Ing-Egr Agosto 2026'!C4:C103,A12) | G12: ═══ TOTAL INGRESOS NT ═══ | J12: =J10
A13: Viático | D13: =SUMIFS('Ing-Egr Agosto 2026'!E4:E103,'Ing-Egr Agosto 2026'!B4:B103,"Ingreso Marco",'Ing-Egr Agosto 2026'!C4:C103,A13)
A14: Animador Bíblico | D14: =SUMIFS('Ing-Egr Agosto 2026'!E4:E103,'Ing-Egr Agosto 2026'!B4:B103,"Ingreso Marco",'Ing-Egr Agosto 2026'!C4:C103,A14)
A15: Otros Ocasionales | D15: =SUMIFS('Ing-Egr Agosto 2026'!E4:E103,'Ing-Egr Agosto 2026'!B4:B103,"Ingreso Marco",'Ing-Egr Agosto 2026'!C4:C103,A15) | I15: =J12
A16: TOTAL MARCO | D16: =SUM(D10:D15)
A17: CLARA | C17: Fecha | D17: Monto
A18: Honorarios Diarios | D18: =SUMIF('Ing-Egr Agosto 2026'!B4:B103,"Ingreso Clara",'Ing-Egr Agosto 2026'!E4:E103)
A19: TOTAL CLARA | D19: =D18
A20: DESDE NEUROTEA | D20: Monto
A21: Salario Admin Marco | D21: 0
A22: Ganancia NT → Familia | D22: 0
A23: Préstamo NT (automático) | D23: =D6
A24: TOTAL DESDE NT | D24: =SUM(D21:D23)
A26: ═══ TOTAL INGRESOS FAMILIA ═══ | D26: =D16+D19+D24
A28: 📉 GASTOS FAMILIARES | G28: 📉 GASTOS NEUROTEA
A29: Detalle | B29: Estado | C29: Monto | D29: Venc. | G29: Detalle | H29: Estado | I29: Monto | J29: Venc.
A30: ► GASTOS FIJOS ✏️ | G30: ► GASTOS FIJOS ✏️
A31: Salario Lili Doméstico | B31: Ninguno | G31: Alquiler 1 (Principal) | H31: Ninguno | I31: 0
A32: Salario Laura Doméstico | B32: Ninguno | G32: Alquiler 2 (Secundario) | H32: Ninguno | I32: 0
A33: Escuela Fabián y Brenda | B33: Ninguno | G33: Limpieza NeuroTEA | H33: Ninguno | I33: 0
A34: Robótica Niños | B34: Ninguno | G34: ► SUELDOS Y HONORARIOS ✏️
A35: ANDE Casa | B35: Ninguno | G35: Sueldo Aracely | H35: Ninguno | I35: 0
A36: Expensa Casa | B36: Ninguno | G36: Sueldo Fátima | H36: Ninguno | I36: 0
A37: Cajubi Marco | B37: Ninguno | G37: Honorario Contador | H37: Ninguno | I37: 0
A38: Mutual Marco | B38: Ninguno | G38: Salario Administrador | H38: Ninguno | I38: 0
A39: Ña Luisa | B39: Ninguno | G39: Honorario Mant. Sistema | H39: Ninguno | I39: 0
A40: Seguro Médico Papá y Mamá | B40: Ninguno | G40: ► TELEFONÍA E INTERNET ✏️
A41: ► CUOTAS Y PRÉSTAMOS ✏️ | G41: Celular Tigo NeuroTEA | H41: Ninguno | I41: 0
A42: Auto Laura Cuota | B42: Ninguno | G42: Celular Tigo Sistema | H42: Ninguno | I42: 0
A43: Coop. Universitaria Clara | B43: Ninguno | G43: WhatsFlow | H43: Ninguno | I43: 0
A44: Coomecipar Clara | B44: Ninguno | G44: Internet NeuroTEA | H44: Ninguno | I44: 0
A45: Tarjeta Cred. Coomecipar | B45: Ninguno | G45: ► IMPUESTOS ✏️
...

Sheet Ing-Egr Septiembre 2026
A1: 📋 REGISTRO DE MOVIMIENTOS - SEPTIEMBRE 2026
A3: Fecha | B3: Tipo | C3: Categoría | D3: Descripción | E3: Ingreso | F3: Egreso | G3: Cuenta | H3: Notas
A104: TOTALES | E104: =SUM(E4:E103) | F104: =SUM(F4:F103)
A106: 📊 RESUMEN DEL MES
A107: INGRESOS: | C107: =SUMIF(B4:B103,"Ingreso NT",E4:E103)
A108: Ingreso NT: | C108: =SUMIF(B4:B103,"Ingreso NT",E4:E103)
A109: Ingreso Marco: | C109: =SUMIF(B4:B103,"Ingreso Marco",E4:E103)
A110: Ingreso Clara: | C110: =SUMIF(B4:B103,"Ingreso Clara",E4:E103)
A111: Devolución Fam → NT: | C111: =SUMIF(B4:B103,"Devolución Familia → NT",E4:E103)
A112: TOTAL INGRESOS: | C112: =SUM(C108:C111)
A113: EGRESOS:
A114: EGRESOS: | C114: =SUMIF(B4:B103,"Egreso NT",F4:F103)
A115: Egreso NT: | C115: =SUMIF(B4:B103,"Egreso NT",F4:F103)
A116: Egreso Familiar: | C116: =SUMIF(B4:B103,"Egreso Familiar",F4:F103)
A117: Préstamo NT → Fam: | C117: =SUMIF(B4:B103,"Préstamo NT → Familia",F4:F103)
A118: TOTAL EGRESOS: | C118: =SUM(C115:C117)
A120: SALDO PRÉSTAMO NT → FAM: | C120: =C117-C111
A121: (Prestado - Devuelto)

Sheet Septiembre 2026
A1: 📊 CONTROL FINANCIERO - SEPTIEMBRE 2026
A3: TOTAL INGRESOS | D3: GASTOS PAGADOS | G3: GASTOS PENDIENTES | J3: BALANCE
A4: =D26+J12 | D4: =D65+I58 | G4: =D66+I59 | J4: =A4-D4-G4
A6: ⚠️ PRÉSTAMO NT → FAMILIA | D6: =SUMIF('Ing-Egr Septiembre 2026'!B4:B103,"Préstamo NT → Familia",'Ing-Egr Septiembre 2026'!F4:F103)-SUMIF('Ing-Egr Septiembre 2026'!B4:B103,"Devolución Familia → NT",'Ing-Egr Septiembre 2026'!E4:E103) | F6: Estado: | G6: =IF(D6=0,"🟢 SANO","🔴 FUGA") | I6: (Ideal = 0)
A8: 💵 INGRESOS FAMILIA | G8: 💵 INGRESOS NEUROTEA
A9: MARCO ITAIPU | C9: Fecha | D9: Monto | G9: Ingreso del Mes | J9: Monto
A10: Salario Mensual | D10: =SUMIFS('Ing-Egr Septiembre 2026'!E4:E103,'Ing-Egr Septiembre 2026'!B4:B103,"Ingreso Marco",'Ing-Egr Septiembre 2026'!C4:C103,A10) | G10: (Suma desde pestaña Ing-Egr Septiembre) | J10: =SUMIF('Ing-Egr Septiembre 2026'!B4:B103,"Ingreso NT",'Ing-Egr Septiembre 2026'!E4:E103)
